# serializer version: 1
# name: test_error_when_dependency_is_defined_in_kwargs_and_annotation
  '''
  ───────────────────────────── Start pytask session ─────────────────────────────
  Platform: <platform> -- Python <version>, pytask <version>, pluggy <version>
  Root: <path>
  Collected 0 tasks.
  
  ────────────────────────── Failures during collection ──────────────────────────
  ─ Could not collect /tmp/pytest-of-tobia/pytest-1709/test_error_when_dependen… ─
  
  ValueError: The value for the parameter 'in_' is defined twice in 
  '@pytask.mark.task(kwargs=...)' and in the type annotation. Choose only one 
  option.
  
  ╭───────────────── Summary ─────────────────╮
  │  1  Collected errors and tasks            │
  │  1  Failed                      (100.0%)  │
  ╰───────────────────────────────────────────╯
  ──────────────────────────── Failed in 0.0 seconds ─────────────────────────────
  '''
# ---
